Workbook

Sheet 2026
A1: Calendar Year 2026 Water Use Projections | B1: =888973-866000 -> 22973 | D1: 909799 | F1: Calendar Year 2026 Water Use Projections | G1: =1118973-1140000 -> -21027 | K1: Calendar Year 2026 Water Use Projections | L1: =863966-725000 -> 138966 | N1: =L1-36365 -> 102601
A2: Most Probable Inflow | D2: =44271+8991-(573/0.9) -> 52625.333 | F2: Probable Minimum Inflow | G2: =1100000-1070865 -> 29135 | K2: Probable Maximum Inflow | N2: =N1-62144 -> 40457
A3: Projected Operating Condition - Level 1 Shortage (1050-1075) | F3: Projected Operating Condition - Level 1 Shortage (1075-1050) | K3: Projected Operating Condition - Level 1 Shortage (1075-1050) | N3: =N2/0.9 -> 44952.222
N4: =N3+62144 -> 107096.22
A5: California | B5: Values in AF | D5: Notes | F5: California | G5: Values in AF | I5: Notes | K5: California | L5: Values in AF | N5: Notes
A6: Basic apportionment | B6: 4400000 | F6: Basic apportionment | G6: 4400000 | K6: Basic apportionment | L6: 4400000
A7: MWD - Storage of NV unused | B7: =B33+B46 -> 0 | F7: MWD - Storage of NV unused | G7: =G33+G46 -> 0 | K7: MWD - Storage of NV unused | L7: 0
A8: MWD - ICS (delivery or creation) | B8: 0 | D8: MWD annual diversion = 907 kaf (want to divert 866 kaf but ICS bank is full); Workaround for rule fail (rule 29) Jan - reset value is 881,590af plus vacated ics 25,409 af = total delivery of 906,999 | F8: MWD - ICS (delivery or creation) | G8: =205448+29135+21027 -> 255610 | I8: MWD Diversion of 1.14 Maf | K8: MWD - ICS (delivery or creation) | L8: 0 | N8: MWD annual diversion = 907 kaf (want to divert 818 kaf but ICS bank is full); Workaround for rule fail (rule 29) Jan - reset value is 881,590af plus vacated ics 25,409 af = total delivery of 906,999
A9: IID - ICS (delivery or creation) | D9: Based on anticipated ICS plan | F9: IID - ICS (delivery or creation) | G9: 0 | K9: IID - ICS (delivery or creation) | L9: 0 | N9: Based on anticipated ICS plan
A10: MWD B2 System Conservation | B10: 0 | F10: MWD B2 System Conservation | K10: MWD B2 System Conservation | L10: 0
A11: California- Water left in Mead | F11: California- Water left in Mead | K11: California- Water left in Mead
A12: System Conservation | B12: =-'System Conservation'!AL2 -> -377609 | F12: System Conservation | G12: =B12 -> -377609 | K12: System Conservation | L12: =-'System Conservation'!AL2 -> -377609
A13: PSCP (Needles) | B13: -145 | F13: PSCP (Needles) | G13: -145 | K13: PSCP (Needles) | L13: -145
A14: Estimated CA adjusted apportionment | B14: =SUM(B6:B13) -> 4022246 | F14: Estimated CA adjusted apportionment | G14: =SUM(G6:G13) -> 4277856 | K14: Estimated CA adjusted apportionment | L14: =SUM(L6:L13) -> 4022246
A15: Modeled CA state total | B15: =B14+B18+B16 -> 4044855 | D15: Input into model | F15: Modeled CA state total | G15: =G14+G16 -> 4277856 | K15: Modeled CA state total | L15: =L14+L16 -> 4022246
A16: Unused - interstate banking | B16: 0 | F16: Unused - interstate banking | G16: 0 | K16: Unused - interstate banking | L16: 0
A17: Unused - left in system | B17: 0 | F17: Unused - left in system | G17: 0 | K17: Unused - left in system | L17: 0
A18: Vacated ICS | B18: =25409-2800 -> 22609 | D18: vacated ics volume of 25,409 af minus MWD return flows | K18: Vacated ICS | L18: =25409-2800 -> 22609 | N18: vacated ics volume of 25,409 af minus MWD return flows
K19: Modeled CA state total | L19: =L15+L18 -> 4044855
A20: Arizona | B20: Values in AF | D20: Notes | F20: Arizona | G20: Values in AF | I20: Notes | K20: Arizona | L20: Values in AF | N20: Notes
A21: Basic apportionment | B21: 2800000 | F21: Basic apportionment | G21: 2800000 | K21: Basic apportionment | L21: 2800000
A22: Shortage volume (IF YEAR 1) | B22: 0 | F22: Shortage volume (IF YEAR 1) | G22: 0 | K22: Shortage volume (IF YEAR 1) | L22: 0
A23: CAP - Storage of NV unused | B23: 0 | D23: CAP annual diversion of 0.808 maf | F23: CAP - Storage of NV unused | G23: 0 | I23: CAP annual diversion of 808 kaf | K23: CAP - Storage of NV unused | L23: 0 | N23: CAP annual diversion of 808 kaf
A24: AZ - ICS (delivery or creation) | B24: 0 | F24: AZ - ICS (delivery or creation) | G24: 0 | K24: AZ - ICS (delivery or creation) | L24: 0
A25: Estimated payback(s) | B25: 0 | F25: Estimated payback(s) | G25: 0 | K25: Estimated payback(s) | L25: 0
A26: PSCP (BHC 2) | B26: -3052 | F26: PSCP (BHC 2) | G26: =B26 -> -3052 | K26: PSCP (BHC 2) | L26: =B26 -> -3052
A27: AZ - System Water | B27: =-SUM('System Conservation'!V2+'System Conservation'!AD2) -> -308313 | D27: See System Conservation tab | F27: AZ - System Water | G27: =B27 -> -308313 | I27: See System Conservation tab | K27: AZ - System Water | L27: =B27 -> -308313 | N27: See System Conservation tab
A28: Estimated AZ adjusted apportionment for Model Input Outyears | B28: =SUM(B21:B27) -> 2488635 | F28: Estimated AZ adjusted apportionment for Model Input Outyears | G28: =SUM(G21:G27) -> 2488635 | K28: Estimated AZ adjusted apportionment for Model Input Outyears | L28: =SUM(L21:L27) -> 2488635
A29: DCP Contribution | B29: -192000 | D29: 192 kaf DCP contribution with 0 af DCP ICS | F29: DCP Contribution | G29: -192000 | I29: 192 kaf DCP contribution with 50 KAF of DCP ICS | K29: DCP Contribution | L29: -192000 | N29: 192 kaf DCP contribution with 0 kaf DCP ICS
A30: CAWCD ICS creation/delivery | B30: 0 | F30: CAWCD ICS creation/delivery | G30: 0 | K30: CAWCD ICS creation/delivery | L30: 0
A31: Shortage Volume if Outyear | B31: -320000 | D31: shortage volume | F31: Shortage Volume if Outyear | G31: -320000 | I31: shortage volume | K31: Shortage Volume if Outyear | L31: -320000
A32: Modeled AZ state total for year 1 | B32: =SUM(B28:B31) -> 1976635 | F32: Modeled AZ state total for year 1 | G32: =SUM(G28:G31) -> 1976635 | K32: Modeled AZ state total for year 1 | L32: =SUM(L28:L31) -> 1976635
A33: Unused - interstate banking | B33: 0 | F33: Unused - interstate banking | G33: 0 | K33: Unused - interstate banking | L33: 0
A34: Unused - left in system | B34: 0 | F34: Unused - left in system | G34: 0 | K34: Unused - left in system | L34: 0
A35: ICS converted to system water due to full bank | B35: 18959 | D35: DCP ICS converted to system water due to full bank | K35: ICS converted to system water due to full bank | L35: 18959 | N35: Conversion of DCPICS to system water to make room for BICS
A36: Nevada | D36: Notes | F36: Nevada | I36: Notes | K36: Nevada | N36: Notes
A37: Basic apportionment | B37: 300000 | F37: Basic apportionment | G37: 300000 | K37: Basic apportionment | L37: 300000
A38: Nevada shortage volume | B38: -13000 | F38: Nevada shortage volume | G38: -13000 | K38: Nevada shortage volume | L38: -13000
A39: SNWA - ICS delivery or creation | B39: 0 | D39: Create 0 | F39: SNWA - ICS Creation | G39: 0 | K39: SNWA - ICS Creation | L39: 0 | N39: intended ICS creation with 199 kaf demand - none created due to full bank
A40: System Conservation (in additon to tributary) | B40: -89000 | D40: Total system conservation is this plus tributary (124 kaf) | F40: System Conservation (in additon to tributary) | G40: -79000 | I40: Total system conservation is this plus tributary (114 kaf) | K40: System Conservation (in additon to tributary) | L40: -99000 | N40: Total system conservation is this plus tributary (134 kaf)
...

Sheet 2027
A1: Calendar Year 2027 Water Use Projections | B1: =952581-950000 -> 2581 | D1: =424/0.9 -> 471.11111 | F1: Calendar Year 2027 Water Use Projections | G1: =1117072+1140000 -> 2257072 | K1: Calendar Year 2027 Water Use Projections | L1: =45259/2 -> 22629.5
A2: Most Probable Inflow | D2: =44271+8991-(573/0.9) -> 52625.333 | F2: Probable Minimum Inflow | G2: =1140000-1112703 -> 27297 | K2: Probable Maximum Inflow | N2: =(49054)/0.9 -> 54504.444
A3: Projected Operating Condition - Level 1 Shortage (1050-1075) | F3: Projected Operating Condition - Level 1 Shortage (1050-1075) | K3: Projected Operating Condition - Level 1 Shortage (1050-1075)
A5: California | B5: Values in AF | D5: Notes | F5: California | G5: Values in AF | I5: Notes | K5: California | L5: Values in AF | N5: Notes
A6: Basic apportionment | B6: 4400000 | F6: Basic apportionment | G6: 4400000 | K6: Basic apportionment | L6: 4400000
A7: MWD - Storage of NV unused | B7: =B33+B46 -> 0 | F7: MWD - Storage of NV unused | G7: =G33+G46 -> 0 | K7: MWD - Storage of NV unused | L7: 0
A8: MWD - ICS (delivery or creation) | B8: 0 | D8: MWD annual diversion = 890 (target is 870 but ICS bank is full) | F8: MWD - ICS (delivery or creation) | G8: =200000+27297+22928 -> 250225 | I8: MWD Diversion of 1.14 Maf | K8: MWD - ICS (delivery or creation) | L8: 0 | N8: MWD annual diversion = 890 kaf (demand is 615 but bank is full)
A9: IID - ICS (delivery or creation) | D9: Based on anticipated ICS plan | F9: IID - ICS (delivery or creation) | G9: 0 | K9: IID - ICS (delivery or creation) | L9: 0 | N9: Based on anticipated ICS plan
A10: MWD B2 System Conservation | F10: MWD B2 System Conservation | K10: MWD B2 System Conservation | L10: 0
A11: California- Water left in Mead | F11: California- Water left in Mead | K11: California- Water left in Mead
A12: System Conservation | B12: =-'System Conservation'!AM2 -> 0 | F12: System Conservation | G12: =B12 -> 0 | K12: System Conservation | L12: =-'System Conservation'!AM2 -> 0
A13: PSCP (Needles) | B13: -145 | F13: PSCP (Needles) | G13: -145 | K13: PSCP (Needles) | L13: -145
A14: Estimated CA adjusted apportionment | B14: =SUM(B6:B13) -> 4399855 | F14: Estimated CA adjusted apportionment | G14: =SUM(G6:G13) -> 4650080 | K14: Estimated CA adjusted apportionment | L14: =SUM(L6:L13) -> 4399855
A15: Modeled CA state total | B15: =B14+B16 -> 4399855 | F15: Modeled CA state total | G15: =G14+G16 -> 4650080 | K15: Modeled CA state total | L15: =L14+L16 -> 4399855
A16: Unused - interstate banking | B16: 0 | F16: Unused - interstate banking | G16: 0 | K16: Unused - interstate banking | L16: 0
A17: Unused - left in system | B17: 0 | F17: Unused - left in system | G17: 0 | K17: Unused - left in system | L17: 0
K18: Vacated ICS | N18: Vacate ECIS to make space for binational
K19: Modeled CA state total | L19: =L15+L18 -> 4399855
A20: Arizona | B20: Values in AF | D20: Notes | F20: Arizona | G20: Values in AF | I20: Notes | K20: Arizona | L20: Values in AF | N20: Notes
A21: Basic apportionment | B21: 2800000 | D21: =50000-1604/0.9 -> 48217.778 | F21: Basic apportionment | G21: 2800000 | K21: Basic apportionment | L21: 2800000
A22: Shortage volume (IF YEAR 1) | B22: 0 | F22: Shortage volume (IF YEAR 1) | G22: 0 | K22: Shortage volume (IF YEAR 1) | L22: 0
A23: CAP - Storage of NV unused | B23: 0 | D23: CAP annual diversion of 978 | F23: CAP - Storage of NV unused | G23: 0 | I23: CAP annual diversion of 985 kaf | K23: CAP - Storage of NV unused | L23: 0 | N23: CAP annual diversion of 978 maf
A24: AZ - ICS (delivery or creation) | B24: 0 | F24: AZ - ICS (delivery or creation) | G24: 0 | K24: AZ - ICS (delivery or creation) | L24: 0
A25: Estimated payback(s) | B25: 0 | F25: Estimated payback(s) | G25: 0 | K25: Estimated payback(s) | L25: 0
A26: PSCP (BHC 2) | B26: 0 | F26: PSCP (BHC 2) | G26: =B26 -> 0 | K26: PSCP (BHC 2) | L26: =B26 -> 0
A27: AZ - System Water | B27: =-SUM('System Conservation'!W2+'System Conservation'!AE2) -> -74805 | D27: See System Conservation tab | F27: AZ - System Water | G27: =B27 -> -74805 | I27: See System Conservation tab | K27: AZ - System Water | L27: =B27 -> -74805 | N27: See System Conservation tab
A28: Estimated AZ adjusted apportionment for Model Input Outyears | B28: =SUM(B21:B27) -> 2725195 | F28: Estimated AZ adjusted apportionment for Model Input Outyears | G28: =SUM(G21:G27) -> 2725195 | K28: Estimated AZ adjusted apportionment for Model Input Outyears | L28: =SUM(L21:L27) -> 2725195
A29: DCP Contribution | B29: -192000 | D29: 192 kaf DCP contribution with 50 kaf DCP ICS | F29: DCP Contribution | G29: -192000 | I29: 192 kaf DCP contribution with 50 KAF of DCP CIS | K29: DCP Contribution | L29: -192000 | N29: 192 kaf DCP contribution with 50 kaf DCP ICS
A30: CAWCD ICS creation/delivery | B30: 45259 | D30: Post 2026 ICS Delivery Logic (45,259 af) | F30: CAWCD ICS creation/delivery | G30: 52390 | I30: Post 2026 ICS Delivery Logic (52,390) | K30: CAWCD ICS creation/delivery | L30: 45259 | N30: Post-2026 delivery
A31: Shortage Volume if Outyear | B31: -320000 | D31: shortage volume | F31: Shortage Volume if Outyear | G31: -320000 | I31: shortage volume | K31: Shortage Volume if Outyear | L31: -320000 | N31: shortage volume
A32: Modeled AZ state total | B32: =SUM(B28:B31) -> 2258454 | F32: Modeled AZ state total | G32: =SUM(G28:G31) -> 2265585 | K32: Modeled AZ state total | L32: =SUM(L28:L31) -> 2258454
A33: Unused - interstate banking | B33: 0 | F33: Unused - interstate banking | G33: 0 | K33: Unused - interstate banking | L33: 0
A34: Unused - left in system | B34: 0 | F34: Unused - left in system | G34: 0 | K34: Unused - left in system | L34: 0
A35: ICS converted to system water due to full bank | B35: 0 | D35: DCP ICS converted to system water due to full bank | K35: ICS converted to system water due to full bank | L35: 0 | N35: Conversion of DCPICS to system water to make room for BICS
A36: Nevada | D36: Notes | F36: Nevada | I36: Notes | K36: Nevada | N36: Notes
A37: Basic apportionment | B37: 300000 | F37: Basic apportionment | G37: 300000 | K37: Basic apportionment | L37: 300000
A38: Nevada shortage volume | B38: -13000 | F38: Nevada shortage volume | G38: -13000 | K38: Nevada shortage volume | L38: -13000
A39: SNWA - ICS delivery or creation | B39: -89000 | D39: intended ICS creation with 198 kaf demand - 9177 AF created due to full bank | F39: SNWA - ICS Creation | G39: -79000 | K39: SNWA - ICS Creation | L39: -99000 | N39: intended ICS creation with 188 kaf demand, 9177 created due to full bank
A40: System Conservation (in additon to tributary) | D40: Total system conservation is this plus tributary (35 kaf) | F40: System Conservation (in additon to tributary) | G40: 0 | I40: Total system conservation is this plus tributary (35 kaf) | K40: System Conservation (in additon to tributary) | L40: 0 | N40: 2027 conservation is only tributary (35 kaf)
A41: DSS taken during shortage | B41: 0 | D41: intended EC ICS creation delivered due to full ICS banks | F41: DSS taken during shortage | G41: 0 | K41: DSS taken during shortage | L41: 0
...

Sheet System Conservation
S1: CY2023 | T1: CY2024 | U1: CY2025 | V1: CY2026 | W1: CY2027 | AA1: CY2023 | AB1: CY2024 | AC1: CY2025 | AD1: CY2026 | AE1: CY2027 | AI1: CY2023 | AJ1: CY2024 | AK1: CY2025 | AL1: CY2026 | AM1: CY2027
B2: LC System Conservation Program | N2: 45077 | S2: =SUM(_xlfn.CHOOSECOLS(_xlfn.ANCHORARRAY(Q5),3)) -> 141400 | T2: =SUM(_xlfn.CHOOSECOLS(_xlfn.ANCHORARRAY(Q5),4)) -> 123400 | U2: =SUM(_xlfn.CHOOSECOLS(_xlfn.ANCHORARRAY(Q5),5)) -> 125503 | V2: =SUM(_xlfn.CHOOSECOLS(_xlfn.ANCHORARRAY(Q5),6)) -> 98800 | W2: =SUM(_xlfn.CHOOSECOLS(_xlfn.ANCHORARRAY(Q5),7)) -> 7224 | AA2: =SUM(_xlfn.CHOOSECOLS(_xlfn.ANCHORARRAY(Y5),3)) -> 178089 | AB2: =SUM(_xlfn.CHOOSECOLS(_xlfn.ANCHORARRAY(Y5),4)) -> 228190.5 | AC2: =SUM(_xlfn.CHOOSECOLS(_xlfn.ANCHORARRAY(Y5),5)) -> 234941.5 | AD2: =SUM(_xlfn.CHOOSECOLS(_xlfn.ANCHORARRAY(Y5),6)) -> 209513 | AE2: =SUM(_xlfn.CHOOSECOLS(_xlfn.ANCHORARRAY(Y5),7)) -> 67581 | AI2: =SUM(_xlfn.CHOOSECOLS(_xlfn.ANCHORARRAY(AG5),3)) -> 225618 | AJ2: =SUM(_xlfn.CHOOSECOLS(_xlfn.ANCHORARRAY(AG5),4)) -> 456096 | AK2: =SUM(_xlfn.CHOOSECOLS(_xlfn.ANCHORARRAY(AG5),5)) -> 428196 | AL2: =SUM(_xlfn.CHOOSECOLS(_xlfn.ANCHORARRAY(AG5),6)) -> 377609 | AM2: =SUM(_xlfn.CHOOSECOLS(_xlfn.ANCHORARRAY(AG5),7)) -> 0
A4: No. | B4: Contractor | C4: Contract Number | D4: CY 2023 | E4: CY 2024 | F4: CY 2025 | G4: CY 2026 | H4: CY 2027 | I4: Total AF | J4: $/AF | K4: Total $ | L4: Status | M4: State | N4: Modeled | O4: Applies to SEIS ROD | Q4: {=_xlfn.CHOOSECOLS(Table1[#Headers],1,2,4,5,6,7,8)} -> No. | R4: Contractor | S4: CY 2023 | T4: CY 2024 | U4: CY 2025 | V4: CY 2026 | W4: CY 2027 | Y4: {=_xlfn.CHOOSECOLS(Table1[#Headers],1,2,4,5,6,7,8)} -> No. | Z4: Contractor | AA4: CY 2023 | AB4: CY 2024 | AC4: CY 2025 | AD4: CY 2026 | AE4: CY 2027 | AG4: {=_xlfn.CHOOSECOLS(Table1[#Headers],1,2,4,5,6,7,8)} -> No. | AH4: Contractor | AI4: CY 2023 | AJ4: CY 2024 | AK4: CY 2025 | AL4: CY 2026 | AM4: CY 2027
A5: 1 | B5: ASARCO | C5: 23-XX-30-W0752 | D5: 14000 | E5: 21000 | F5: 21000 | G5: 21000 | I5: =SUM(Table1[[#This Row],[CY 2023]:[CY 2026]]) -> 77000 | J5: 400 | K5: =I5*J5 -> 30800000 | L5: Executed July 6 | M5: AZ-CAWCD | N5: Yes | O5: Yes | Q5: {=_xlfn.CHOOSECOLS(_xlfn._xlws.FILTER(Table1[], (Table1[Modeled]="Yes")*(Table1[State] = "AZ-CAWCD")),1,2,4,5,6,7,8)} -> 1 | R5: ASARCO | S5: 14000 | T5: 21000 | U5: 21000 | V5: 21000 | W5: 0 | Y5: {=_xlfn.CHOOSECOLS(_xlfn._xlws.FILTER(Table1[], (Table1[Modeled]="Yes")*(Table1[State] <> "AZ-CAWCD")*(Table1[State] <> "CA")*(Table1[State] <> "CA-Tribe")),1,2,4,5,6,7,8)} -> 9 | Z5: FMYN | AA5: 13933 | AB5: 13933 | AC5: 13933 | AD5: 13933 | AE5: 0 | AG5: {=_xlfn.CHOOSECOLS(_xlfn._xlws.FILTER(Table1[], (Table1[Modeled]="Yes")*(Table1[State] = "CA")),1,2,4,5,6,7,8)} -> 14 | AH5: CVWD Grd Wtr Replnt | AI5: 35000 | AJ5: 35000 | AK5: 35000 | AL5: 35000 | AM5: 0
A6: 2 | B6: Gilbert | C6: 23-XX-30-W0759 | D6: 1200 | E6: 800 | F6: 800 | G6: 1600 | H6: 767 | I6: =SUM(Table1[[#This Row],[CY 2023]:[CY 2026]]) -> 4400 | J6: 400 | K6: =I6*J6 -> 1760000 | L6: Executed June 28 | M6: AZ-CAWCD | N6: Yes | O6: Yes | Q6: 2 | R6: Gilbert | S6: 1200 | T6: 800 | U6: 800 | V6: 1600 | W6: 767 | Y6: 10 | Z6: GRIC | AA6: 91319 | AB6: 125000 | AC6: 119561 | AD6: 75363 | AE6: 67581 | AG6: 18 | AH6: IID 2023-2026 | AI6: 106111 | AJ6: 257640 | AK6: 250000 | AL6: 192360 | AM6: 0
A7: 3 | B7: Glendale | C7: 23-XX-30-W0778 | D7: 7000 | E7: 1000 | F7: =7000-2897 -> 4103 | G7: 7000 | I7: =SUM(Table1[[#This Row],[CY 2023]:[CY 2026]]) -> 19103 | J7: 400 | K7: =I7*J7 -> 7641200 | L7: Executed July 10 | M7: AZ-CAWCD | N7: Yes | O7: Yes | Q7: 3 | R7: Glendale | S7: 7000 | T7: 1000 | U7: 4103 | V7: 7000 | W7: 0 | Y7: 11 | Z7: SCAT | AA7: 23804 | AB7: 23451 | AC7: 23451 | AD7: 23451 | AE7: 0 | AG7: 20 | AH7: Bard | AI7: 0 | AJ7: 5700 | AK7: 9286 | AL7: 11400 | AM7: 0
A8: 4 | B8: Metro Water Dist | C8: 23-XX-30-W0757 | D8: 5000 | E8: 5000 | F8: 5000 | G8: 5000 | I8: =SUM(Table1[[#This Row],[CY 2023]:[CY 2026]]) -> 20000 | J8: 400 | K8: =I8*J8 -> 8000000 | L8: Executed May 24 | M8: AZ-CAWCD | N8: Yes | O8: Yes | Q8: 4 | R8: Metro Water Dist | S8: 5000 | T8: 5000 | U8: 5000 | V8: 5000 | W8: 0 | Y8: 12 | Z8: GM Gabrych/Matador | AA8: 3240 | AB8: 3240 | AC8: 3240 | AD8: 3240 | AE8: 0 | AG8: 21 | AH8: Quechan | AI8: 13000 | AJ8: 13000 | AK8: 13000 | AL8: 13000 | AM8: 0
A9: 5 | B9: Peoria | C9: 23-XX-30-W0753 | D9: 7200 | E9: 7200 | F9: 7200 | G9: 5000 | I9: =SUM(Table1[[#This Row],[CY 2023]:[CY 2026]]) -> 26600 | J9: 400 | K9: =I9*J9 -> 10640000 | L9: Executed May 26 | M9: AZ-CAWCD | N9: Yes | O9: Yes | Q9: 5 | R9: Peoria | S9: 7200 | T9: 7200 | U9: 7200 | V9: 5000 | W9: 0 | Y9: 13 | Z9: MVIDD | AA9: 12812 | AB9: 13293 | AC9: 13694 | AD9: 14184 | AE9: 0 | AG9: 22 | AH9: CVWD Fallowing | AI9: 0 | AJ9: 725 | AK9: 3889 | AL9: 6511 | AM9: 0
A10: 6 | B10: Phoenix | C10: 23-XX-30-W0754 | D10: 50000 | E10: 50000 | F10: 50000 | I10: =SUM(Table1[[#This Row],[CY 2023]:[CY 2026]]) -> 150000 | J10: 400 | K10: =I10*J10 -> 60000000 | L10: Executed June 21 | M10: AZ-CAWCD | N10: Yes | O10: Yes | Q10: 6 | R10: Phoenix | S10: 50000 | T10: 50000 | U10: 50000 | V10: 0 | W10: 0 | Y10: 15 | Z10: Cathcart | AA10: 57 | AB10: 60.5 | AC10: 60.5 | AD10: 61 | AE10: 0 | AG10: 25 | AH10: PVID | AI10: 71507 | AJ10: 117021 | AK10: 117021 | AL10: 119338 | AM10: 0
A11: 7 | B11: Scottsdale | C11: 23-XX-30-W0755 | D11: 7000 | E11: 6000 | F11: 5000 | G11: 4000 | H11: 2800 | I11: =SUM(Table1[[#This Row],[CY 2023]:[CY 2026]]) -> 22000 | J11: 400 | K11: =I11*J11 -> 8800000 | L11: Executed July 18 | M11: AZ-CAWCD | N11: Yes | O11: Yes | Q11: 7 | R11: Scottsdale | S11: 7000 | T11: 6000 | U11: 5000 | V11: 4000 | W11: 2800 | Y11: 16 | Z11: YMIDD | AA11: 21556 | AB11: 21657 | AC11: 23615 | AD11: 23893 | AE11: 0 | AG11: 26 | AH11: MWD (B2) | AI11: 0 | AJ11: 27010 | AK11: 0 | AL11: 0 | AM11: 0
A12: 8 | B12: Tucson | C12: 23-XX-30-W0756 | D12: 50000 | E12: 30000 | F12: 30000 | G12: 52800 | H12: 3657 | I12: =SUM(Table1[[#This Row],[CY 2023]:[CY 2026]]) -> 162800 | J12: 400 | K12: =I12*J12 -> 65120000 | L12: Executed May 24 | M12: AZ-CAWCD | N12: Yes | O12: Yes | Q12: 8 | R12: Tucson | S12: 50000 | T12: 30000 | U12: 30000 | V12: 52800 | W12: 3657 | Y12: 17 | Z12: CVIDD | AA12: 1682 | AB12: 2328 | AC12: 2328 | AD12: 2329 | AE12: 0
A13: 9 | B13: FMYN | C13: 23-XX-30-W0750 | D13: 13933 | E13: 13933 | F13: 13933 | G13: 13933 | I13: =SUM(Table1[[#This Row],[CY 2023]:[CY 2026]]) -> 55732 | J13: 400 | K13: =J13*I13 -> 22292800 | L13: Executed March 10 | M13: AZ-Tribe | N13: Yes | O13: Yes | Q13: 24 | R13: Spanish Trail Water Company | S13: 0 | T13: 2400 | U13: 2400 | V13: 2400 | W13: 0 | Y13: 19 | Z13: Hopi | AA13: 2679 | AB13: 3059 | AC13: 3059 | AD13: 3059 | AE13: 0
A14: 10 | B14: GRIC | C14: 23-XX-30-W0760 | D14: 91319 | E14: 125000 | F14: 119561 | G14: 75363 | H14: 67581 | I14: =SUM(Table1[[#This Row],[CY 2023]:[CY 2026]]) -> 411243 | J14: 400 | K14: =I14*J14 -> 164497200 | L14: Executed April 6 | M14: AZ-Tribe | N14: Yes | O14: Yes | Y14: 23 | Z14: 242 Wellfield | AA14: 7007 | AB14: 22169 | AC14: 32000 | AD14: 50000 | AE14: 0
A15: 11 | B15: SCAT | C15: 23-XX-30-W0765 | D15: 23804 | E15: 23451 | F15: 23451 | G15: 23451 | I15: =SUM(Table1[[#This Row],[CY 2023]:[CY 2026]]) -> 94157 | J15: 330 | K15: =I15*J15 -> 31071810 | L15: Executed July 3 | M15: AZ-Tribe | N15: Yes | O15: Yes
B16: TON | C16: 23-XX-30-W0751 | E16: 0 | F16: 0 | I16: =SUM(Table1[[#This Row],[CY 2023]:[CY 2026]]) -> 0 | K16: =I16*J16 -> 0 | L16: PXAO developing a firming agreement with TON instead of a SCIA. | M16: AZ-Tribe | N16: No
A17: 12 | B17: GM Gabrych/Matador | C17: 23-XX-30-W0774 | D17: 3240 | E17: 3240 | F17: 3240 | G17: 3240 | I17: =SUM(Table1[[#This Row],[CY 2023]:[CY 2026]]) -> 12960 | J17: 400 | K17: =I17*J17 -> 5184000 | L17: Executed June 6 | M17: AZ-Other | N17: Yes | O17: Yes
A18: 13 | B18: MVIDD | C18: 23-XX-30-W0770 | D18: 12812 | E18: 13293 | F18: 13694 | G18: 14184 | I18: =SUM(Table1[[#This Row],[CY 2023]:[CY 2026]]) -> 53983 | J18: 400 | K18: TBD | L18: Executed August 16 | M18: AZ-Other | N18: Yes | O18: Yes
A19: 14 | B19: CVWD Grd Wtr Replnt | C19: 23-XX-30-W0764 | D19: 35000 | E19: 35000 | F19: 35000 | G19: 35000 | I19: =SUM(Table1[[#This Row],[CY 2023]:[CY 2026]]) -> 140000 | J19: 400 | K19: =I19*J19 -> 56000000 | L19: Executed July 24 | M19: CA | N19: Yes | O19: Yes
A20: 15 | B20: Cathcart | C20: 23-XX-30-W0776 | D20: 57 | E20: 60.5 | F20: 60.5 | G20: 61 | I20: =SUM(Table1[[#This Row],[CY 2023]:[CY 2026]]) -> 239 | J20: 400 | K20: =I20*J20 -> 95600 | L20: Executed August 16 | M20: AZ-Other | N20: Yes | O20: Yes
A21: 16 | B21: YMIDD | C21: 23-XX-30-W0769 | D21: 21556 | E21: 21657 | F21: 23615 | G21: 23893 | I21: =SUM(Table1[[#This Row],[CY 2023]:[CY 2026]]) -> 90721 | L21: Executed August 16 | M21: AZ-Other | N21: Yes | O21: Yes
A22: 17 | B22: CVIDD | C22: 23-XX-30-W0771 | D22: 1682 | E22: 2328 | F22: 2328 | G22: 2329 | I22: =SUM(Table1[[#This Row],[CY 2023]:[CY 2026]]) -> 8667 | L22: Executed July 5 | M22: AZ-Other | N22: Yes | O22: Yes
A23: 18 | B23: IID 2023-2026 | D23: 106111 | E23: 257640 | F23: 250000 | G23: 192360 | I23: =SUM(Table1[[#This Row],[CY 2023]:[CY 2026]]) -> 806111 | L23: Executed TBD | M23: CA | N23: Yes | O23: Yes
A24: 19 | B24: Hopi | C24: 23-Xx-30-W0779 | D24: 2679 | E24: 3059 | F24: 3059 | G24: 3059 | I24: =SUM(Table1[[#This Row],[CY 2023]:[CY 2026]]) -> 11856 | L24: Executed October 27 | M24: AZ-Other | N24: Yes | O24: Yes
A25: 20 | B25: Bard | C25: 23-XX-30-W0773 | E25: 5700 | F25: 9286 | G25: 11400 | I25: =SUM(Table1[[#This Row],[CY 2023]:[CY 2026]]) -> 26386 | L25: TBD | M25: CA | N25: Yes | O25: Yes
A26: 21 | B26: Quechan | C26: 23-XX-30-W0783 | D26: 13000 | E26: 13000 | F26: 13000 | G26: 13000 | I26: =SUM(Table1[[#This Row],[CY 2023]:[CY 2026]]) -> 52000 | L26: Quechan Tribe, MWD, and US intend to execute SCIA at CRWUA. | M26: CA | N26: Yes | O26: Yes
A27: 22 | B27: CVWD Fallowing | E27: 725 | F27: 3889 | G27: 6511 | I27: =SUM(Table1[[#This Row],[CY 2023]:[CY 2026]]) -> 11125 | L27: Technical information to be developed for on-farm efficiency activity that CVWD will use as well as fallowing. | M27: CA | N27: Yes
A28: 23 | B28: 242 Wellfield | D28: 7007 | E28: 22169 | F28: 32000 | G28: 50000 | I28: =SUM(Table1[[#This Row],[CY 2023]:[CY 2026]]) -> 111176 | L28: Executed | M28: AZ-Other | N28: Yes | O28: Yes
A29: 24 | B29: Spanish Trail Water Company | D29: 0 | E29: 2400 | F29: 2400 | G29: 2400 | I29: =SUM(Table1[[#This Row],[CY 2023]:[CY 2026]]) -> 7200 | L29: SCIA sent to Spanish Trail for review July 18. Spanish Trail has indicated it concurs with the SCIA and has no comments or changes. | M29: AZ-CAWCD | N29: Yes
A30: 25 | B30: PVID | D30: 71507 | E30: 117021 | F30: 117021 | G30: =83272+36066 -> 119338 | I30: =SUM(Table1[[#This Row],[CY 2023]:[CY 2026]]) -> 424887 | L30: Executed | M30: CA | N30: Yes | O30: Yes
A31: 26 | B31: MWD (B2) | E31: 27010 | I31: =SUM(Table1[[#This Row],[CY 2023]:[CY 2026]]) -> 27010 | L31: Pending | M31: CA | N31: Yes | O31: Yes
S32: 2023 | T32: 2024 | U32: 2025 | V32: 2026
R33: Total | S33: =SUM(S2,AA2,AI2) -> 545107 | T33: =SUM(T2,AB2,AJ2) -> 807686.5 | U33: =SUM(U2,AC2,AK2) -> 788640.5 | V33: =SUM(V2,AD2,AL2) -> 685922
R35: Cummulative | S35: =S33 -> 545107 | T35: =S35+T33 -> 1352793.5 | U35: =T35+U33 -> 2141434 | V35: =U35+V33 -> 2827356
R38: Feet | S38: =S35/77000 -> 7.0793117 | T38: =T35/77000 -> 17.568747 | U38: =U35/77000 -> 27.810831 | V38: =V35/77000 -> 36.718909
R41: IID | S41: =700000/77000 -> 9.0909091

Sheet SysCon SummaryTable
W2: State | X2: LCB Water Entitlement Holder/Tribe | Y2: 2023 | Z2: 2024 | AA2: 2025 | AB2: 2026 | AC2: Total
E3: Conservation Activity (AF) | F3: 2023 | G3: 2024 | H3: 2025 | I3: 2026 | K3: Total | W3: AZ | X3: Central Arizona Project (CAP) Other Conserved Water | Y3: 41776 | Z3: 0 | AA3: 0 | AB3: 0 | AC3: =SUM(Y3:AB3) -> 41776
A4: =MATCH(E4,$E$28:$E$47,0) -> 1 | E4: CAP System Conservation Agreements | F4: {=SUM(_xlfn._xlws.FILTER(Table1[CY 2023], (Table1[Modeled]="Yes")*(Table1[State] = "AZ-CAWCD")))} -> 141400 | G4: {=SUM(_xlfn._xlws.FILTER(Table1[CY 2024], (Table1[Modeled]="Yes")*(Table1[State] = "AZ-CAWCD")))} -> 123400 | H4: {=SUM(_xlfn._xlws.FILTER(Table1[CY 2025], (Table1[Modeled]="Yes")*(Table1[State] = "AZ-CAWCD")))} -> 125503 | I4: {=SUM(_xlfn._xlws.FILTER(Table1[CY 2026], (Table1[Modeled]="Yes")*(Table1[State] = "AZ-CAWCD")))} -> 98800 | K4: =SUM(F4:I4) -> 489103 | X4: CAP Subcontractors System Conservation Water (SCW) | Y4: {=SUM(_xlfn._xlws.FILTER(Table1[CY 2023], (Table1[Modeled]="Yes")*(Table1[State] = "AZ-CAWCD")))} -> 141400 | Z4: {=SUM(_xlfn._xlws.FILTER(Table1[CY 2024], (Table1[Modeled]="Yes")*(Table1[State] = "AZ-CAWCD")))} -> 123400 | AA4: {=SUM(_xlfn._xlws.FILTER(Table1[CY 2025], (Table1[Modeled]="Yes")*(Table1[State] = "AZ-CAWCD")))} -> 125503 | AB4: {=SUM(_xlfn._xlws.FILTER(Table1[CY 2026], (Table1[Modeled]="Yes")*(Table1[State] = "AZ-CAWCD")))} -> 98800 | AC4: =SUM(Y4:AB4) -> 489103
A5: =MATCH(E5,$E$28:$E$47,0) -> 4 | E5: Fort McDowell Yavapai Nation System Conservation | F5: {=_xlfn._xlws.FILTER(Table1[CY 2023],(Table1[Contractor]="FMYN"))} -> 13933 | G5: {=_xlfn._xlws.FILTER(Table1[CY 2024],(Table1[Contractor]="FMYN"))} -> 13933 | H5: {=_xlfn._xlws.FILTER(Table1[CY 2025],(Table1[Contractor]="FMYN"))} -> 13933 | I5: {=_xlfn._xlws.FILTER(Table1[CY 2026],(Table1[Contractor]="FMYN"))} -> 13933 | K5: =SUM(F5:I5) -> 55732 | X5: Cathcart Farms SCW | Y5: {=_xlfn._xlws.FILTER(Table1[CY 2023],(Table1[Contractor]="Cathcart"))} -> 57 | Z5: {=_xlfn._xlws.FILTER(Table1[CY 2024],(Table1[Contractor]="Cathcart"))} -> 60.5 | AA5: {=_xlfn._xlws.FILTER(Table1[CY 2025],(Table1[Contractor]="Cathcart"))} -> 60.5 | AB5: {=_xlfn._xlws.FILTER(Table1[CY 2026],(Table1[Contractor]="Cathcart"))} -> 61 | AC5: =SUM(Y5:AB5) -> 239
A6: =MATCH(E6,$E$28:$E$47,0) -> 9 | E6: San Carlos Apache Tribe System Conservation | F6: {=_xlfn._xlws.FILTER(Table1[CY 2023],(Table1[Contractor]="SCAT"))} -> 23804 | G6: {=_xlfn._xlws.FILTER(Table1[CY 2024],(Table1[Contractor]="SCAT"))} -> 23451 | H6: {=_xlfn._xlws.FILTER(Table1[CY 2025],(Table1[Contractor]="SCAT"))} -> 23451 | I6: {=_xlfn._xlws.FILTER(Table1[CY 2026],(Table1[Contractor]="SCAT"))} -> 23451 | K6: =SUM(F6:I6) -> 94157 | X6: Cibola Valley Irrigation & Drainage District SCW | Y6: {=_xlfn._xlws.FILTER(Table1[CY 2023],(Table1[Contractor]="CVIDD"))} -> 1682 | Z6: {=_xlfn._xlws.FILTER(Table1[CY 2024],(Table1[Contractor]="CVIDD"))} -> 2328 | AA6: {=_xlfn._xlws.FILTER(Table1[CY 2025],(Table1[Contractor]="CVIDD"))} -> 2328 | AB6: {=_xlfn._xlws.FILTER(Table1[CY 2026],(Table1[Contractor]="CVIDD"))} -> 2329 | AC6: =SUM(Y6:AB6) -> 8667
A7: =MATCH(E7,$E$28:$E$47,0) -> 12 | E7: Coachella Groundwater System Conservation | F7: {=_xlfn._xlws.FILTER(Table1[CY 2023],(Table1[Contractor]="CVWD Grd Wtr Replnt"))} -> 35000 | G7: {=_xlfn._xlws.FILTER(Table1[CY 2024],(Table1[Contractor]="CVWD Grd Wtr Replnt"))} -> 35000 | H7: {=_xlfn._xlws.FILTER(Table1[CY 2025],(Table1[Contractor]="CVWD Grd Wtr Replnt"))} -> 35000 | I7: {=_xlfn._xlws.FILTER(Table1[CY 2026],(Table1[Contractor]="CVWD Grd Wtr Replnt"))} -> 35000 | K7: =SUM(F7:I7) -> 140000 | X7: Fort McDowell Yavapai Nation SCW | Y7: {=_xlfn._xlws.FILTER(Table1[CY 2023],(Table1[Contractor]="FMYN"))} -> 13933 | Z7: {=_xlfn._xlws.FILTER(Table1[CY 2024],(Table1[Contractor]="FMYN"))} -> 13933 | AA7: {=_xlfn._xlws.FILTER(Table1[CY 2025],(Table1[Contractor]="FMYN"))} -> 13933 | AB7: {=_xlfn._xlws.FILTER(Table1[CY 2026],(Table1[Contractor]="FMYN"))} -> 13933 | AC7: =SUM(Y7:AB7) -> 55732
A8: =MATCH(E8,$E$28:$E$47,0) -> 13 | E8: Coachella Ag Conservation System Conservation | F8: {=_xlfn._xlws.FILTER(Table1[CY 2023],(Table1[Contractor]="CVWD Fallowing"))} -> 0 | G8: {=_xlfn._xlws.FILTER(Table1[CY 2024],(Table1[Contractor]="CVWD Fallowing"))} -> 725 | H8: {=_xlfn._xlws.FILTER(Table1[CY 2025],(Table1[Contractor]="CVWD Fallowing"))} -> 3889 | I8: {=_xlfn._xlws.FILTER(Table1[CY 2026],(Table1[Contractor]="CVWD Fallowing"))} -> 6511 | K8: =SUM(F8:I8) -> 11125 | X8: GM Gabrych Family Limited Partnership SCW | Y8: {=_xlfn._xlws.FILTER(Table1[CY 2023],(Table1[Contractor]="GM Gabrych/Matador"))} -> 3240 | Z8: {=_xlfn._xlws.FILTER(Table1[CY 2024],(Table1[Contractor]="GM Gabrych/Matador"))} -> 3240 | AA8: {=_xlfn._xlws.FILTER(Table1[CY 2025],(Table1[Contractor]="GM Gabrych/Matador"))} -> 3240 | AB8: {=_xlfn._xlws.FILTER(Table1[CY 2026],(Table1[Contractor]="GM Gabrych/Matador"))} -> 3240 | AC8: =SUM(Y8:AB8) -> 12960
A9: =MATCH(E9,$E$28:$E$47,0) -> 6 | E9: GRIC System Conservation | F9: {=_xlfn._xlws.FILTER(Table1[CY 2023],(Table1[Contractor]="GRIC"))} -> 91319 | G9: {=_xlfn._xlws.FILTER(Table1[CY 2024],(Table1[Contractor]="GRIC"))} -> 125000 | H9: {=_xlfn._xlws.FILTER(Table1[CY 2025],(Table1[Contractor]="GRIC"))} -> 119561 | I9: {=_xlfn._xlws.FILTER(Table1[CY 2026],(Table1[Contractor]="GRIC"))} -> 75363 | K9: =SUM(F9:I9) -> 411243 | X9: Gila River Indian Community SCW | Y9: {=_xlfn._xlws.FILTER(Table1[CY 2023],(Table1[Contractor]="GRIC"))} -> 91319 | Z9: {=_xlfn._xlws.FILTER(Table1[CY 2024],(Table1[Contractor]="GRIC"))} -> 125000 | AA9: {=_xlfn._xlws.FILTER(Table1[CY 2025],(Table1[Contractor]="GRIC"))} -> 119561 | AB9: {=_xlfn._xlws.FILTER(Table1[CY 2026],(Table1[Contractor]="GRIC"))} -> 75363 | AC9: =SUM(Y9:AB9) -> 411243
A10: =MATCH(E10,$E$28:$E$47,0) -> 3 | E10: Cibola Valley IDD System Conservation | F10: {=_xlfn._xlws.FILTER(Table1[CY 2023],(Table1[Contractor]="CVIDD"))} -> 1682 | G10: {=_xlfn._xlws.FILTER(Table1[CY 2024],(Table1[Contractor]="CVIDD"))} -> 2328 | H10: {=_xlfn._xlws.FILTER(Table1[CY 2025],(Table1[Contractor]="CVIDD"))} -> 2328 | I10: {=_xlfn._xlws.FILTER(Table1[CY 2026],(Table1[Contractor]="CVIDD"))} -> 2329 | K10: =SUM(F10:I10) -> 8667 | X10: Hopi Tribe SCW | Y10: {=_xlfn._xlws.FILTER(Table1[CY 2023],(Table1[Contractor]="Hopi"))} -> 2679 | Z10: {=_xlfn._xlws.FILTER(Table1[CY 2024],(Table1[Contractor]="Hopi"))} -> 3059 | AA10: {=_xlfn._xlws.FILTER(Table1[CY 2025],(Table1[Contractor]="Hopi"))} -> 3059 | AB10: {=_xlfn._xlws.FILTER(Table1[CY 2026],(Table1[Contractor]="Hopi"))} -> 3059 | AC10: =SUM(Y10:AB10) -> 11856
A11: =MATCH(E11,$E$28:$E$47,0) -> 5 | E11: GM Gabrych System Conservation | F11: {=_xlfn._xlws.FILTER(Table1[CY 2023],(Table1[Contractor]="GM Gabrych/Matador"))} -> 3240 | G11: {=_xlfn._xlws.FILTER(Table1[CY 2024],(Table1[Contractor]="GM Gabrych/Matador"))} -> 3240 | H11: {=_xlfn._xlws.FILTER(Table1[CY 2025],(Table1[Contractor]="GM Gabrych/Matador"))} -> 3240 | I11: {=_xlfn._xlws.FILTER(Table1[CY 2026],(Table1[Contractor]="GM Gabrych/Matador"))} -> 3240 | K11: =SUM(F11:I11) -> 12960 | X11: Mohave Valley Irrigation & Drainage District SCW | Y11: {=_xlfn._xlws.FILTER(Table1[CY 2023],(Table1[Contractor]="MVIDD"))} -> 12812 | Z11: {=_xlfn._xlws.FILTER(Table1[CY 2024],(Table1[Contractor]="MVIDD"))} -> 13293 | AA11: {=_xlfn._xlws.FILTER(Table1[CY 2025],(Table1[Contractor]="MVIDD"))} -> 13694 | AB11: {=_xlfn._xlws.FILTER(Table1[CY 2026],(Table1[Contractor]="MVIDD"))} -> 14184 | AC11: =SUM(Y11:AB11) -> 53983
A12: =MATCH(E12,$E$28:$E$47,0) -> 2 | E12: Cathcart Farms System Conservation | F12: {=_xlfn._xlws.FILTER(Table1[CY 2023],(Table1[Contractor]="Cathcart"))} -> 57 | G12: {=_xlfn._xlws.FILTER(Table1[CY 2024],(Table1[Contractor]="Cathcart"))} -> 60.5 | H12: {=_xlfn._xlws.FILTER(Table1[CY 2025],(Table1[Contractor]="Cathcart"))} -> 60.5 | I12: {=_xlfn._xlws.FILTER(Table1[CY 2026],(Table1[Contractor]="Cathcart"))} -> 61 | K12: =SUM(F12:I12) -> 239 | X12: San Carlos Apache Tribe SCW | Y12: {=_xlfn._xlws.FILTER(Table1[CY 2023],(Table1[Contractor]="SCAT"))} -> 23804 | Z12: {=_xlfn._xlws.FILTER(Table1[CY 2024],(Table1[Contractor]="SCAT"))} -> 23451 | AA12: {=_xlfn._xlws.FILTER(Table1[CY 2025],(Table1[Contractor]="SCAT"))} -> 23451 | AB12: {=_xlfn._xlws.FILTER(Table1[CY 2026],(Table1[Contractor]="SCAT"))} -> 23451 | AC12: =SUM(Y12:AB12) -> 94157
A13: =MATCH(E13,$E$28:$E$47,0) -> 10 | E13: YMIDD System Conservation | F13: {=_xlfn._xlws.FILTER(Table1[CY 2023],(Table1[Contractor]="YMIDD"))} -> 21556 | G13: {=_xlfn._xlws.FILTER(Table1[CY 2024],(Table1[Contractor]="YMIDD"))} -> 21657 | H13: {=_xlfn._xlws.FILTER(Table1[CY 2025],(Table1[Contractor]="YMIDD"))} -> 23615 | I13: {=_xlfn._xlws.FILTER(Table1[CY 2026],(Table1[Contractor]="YMIDD"))} -> 23893 | K13: =SUM(F13:I13) -> 90721 | X13: Yuma Mesa Irrigation & Drainage District SCW | Y13: {=_xlfn._xlws.FILTER(Table1[CY 2023],(Table1[Contractor]="YMIDD"))} -> 21556 | Z13: {=_xlfn._xlws.FILTER(Table1[CY 2024],(Table1[Contractor]="YMIDD"))} -> 21657 | AA13: {=_xlfn._xlws.FILTER(Table1[CY 2025],(Table1[Contractor]="YMIDD"))} -> 23615 | AB13: {=_xlfn._xlws.FILTER(Table1[CY 2026],(Table1[Contractor]="YMIDD"))} -> 23893 | AC13: =SUM(Y13:AB13) -> 90721
A14: =MATCH(E14,$E$28:$E$47,0) -> 8 | E14: MVIDD System Conservation | F14: {=_xlfn._xlws.FILTER(Table1[CY 2023],(Table1[Contractor]="MVIDD"))} -> 12812 | G14: {=_xlfn._xlws.FILTER(Table1[CY 2024],(Table1[Contractor]="MVIDD"))} -> 13293 | H14: {=_xlfn._xlws.FILTER(Table1[CY 2025],(Table1[Contractor]="MVIDD"))} -> 13694 | I14: {=_xlfn._xlws.FILTER(Table1[CY 2026],(Table1[Contractor]="MVIDD"))} -> 14184 | K14: =SUM(F14:I14) -> 53983 | W14: CA | X14: Coachella Valley Water District SCW | Y14: {=_xlfn._xlws.FILTER(Table1[CY 2023],(Table1[Contractor]="CVWD Grd Wtr Replnt"))} -> 35000 | Z14: {=_xlfn._xlws.FILTER(Table1[CY 2024],(Table1[Contractor]="CVWD Grd Wtr Replnt"))} -> 35000 | AA14: {=_xlfn._xlws.FILTER(Table1[CY 2025],(Table1[Contractor]="CVWD Grd Wtr Replnt"))} -> 35000 | AB14: {=_xlfn._xlws.FILTER(Table1[CY 2026],(Table1[Contractor]="CVWD Grd Wtr Replnt"))} -> 35000 | AC14: =SUM(Y14:AB14) -> 140000
A15: =MATCH(E15,$E$28:$E$47,0) -> 7 | E15: Hopi Tribe System Conservation | F15: {=_xlfn._xlws.FILTER(Table1[CY 2023],(Table1[Contractor]="Hopi"))} -> 2679 | G15: {=_xlfn._xlws.FILTER(Table1[CY 2024],(Table1[Contractor]="Hopi"))} -> 3059 | H15: {=_xlfn._xlws.FILTER(Table1[CY 2025],(Table1[Contractor]="Hopi"))} -> 3059 | I15: {=_xlfn._xlws.FILTER(Table1[CY 2026],(Table1[Contractor]="Hopi"))} -> 3059 | K15: =SUM(F15:I15) -> 11856 | X15: Coachella Agriculture SCW | Y15: {=_xlfn._xlws.FILTER(Table1[CY 2023],(Table1[Contractor]="CVWD Fallowing"))} -> 0 | Z15: {=_xlfn._xlws.FILTER(Table1[CY 2024],(Table1[Contractor]="CVWD Fallowing"))} -> 725 | AA15: {=_xlfn._xlws.FILTER(Table1[CY 2025],(Table1[Contractor]="CVWD Fallowing"))} -> 3889 | AB15: {=_xlfn._xlws.FILTER(Table1[CY 2026],(Table1[Contractor]="CVWD Fallowing"))} -> 6511 | AC15: =SUM(Y15:AB15) -> 11125
A16: =MATCH(E16,$E$28:$E$47,0) -> 14 | E16: IID System Conservation | F16: {=_xlfn._xlws.FILTER(Table1[CY 2023],(Table1[Contractor]="IID 2023-2026"))} -> 106111 | G16: {=_xlfn._xlws.FILTER(Table1[CY 2024],(Table1[Contractor]="IID 2023-2026"))} -> 257640 | H16: {=_xlfn._xlws.FILTER(Table1[CY 2025],(Table1[Contractor]="IID 2023-2026"))} -> 250000 | I16: {=_xlfn._xlws.FILTER(Table1[CY 2026],(Table1[Contractor]="IID 2023-2026"))} -> 192360 | K16: =SUM(F16:I16) -> 806111 | X16: Imperial Irrigation District SCW | Y16: {=_xlfn._xlws.FILTER(Table1[CY 2023],(Table1[Contractor]="IID 2023-2026"))} -> 106111 | Z16: {=_xlfn._xlws.FILTER(Table1[CY 2024],(Table1[Contractor]="IID 2023-2026"))} -> 257640 | AA16: {=_xlfn._xlws.FILTER(Table1[CY 2025],(Table1[Contractor]="IID 2023-2026"))} -> 250000 | AB16: {=_xlfn._xlws.FILTER(Table1[CY 2026],(Table1[Contractor]="IID 2023-2026"))} -> 192360 | AC16: =SUM(Y16:AB16) -> 806111
A17: =MATCH(E17,$E$28:$E$47,0) -> 16 | E17: Quechan Indian Tribe-MWD System Conservation | F17: {=_xlfn._xlws.FILTER(Table1[CY 2023],(Table1[Contractor]="Quechan"))} -> 13000 | G17: {=_xlfn._xlws.FILTER(Table1[CY 2024],(Table1[Contractor]="Quechan"))} -> 13000 | H17: {=_xlfn._xlws.FILTER(Table1[CY 2025],(Table1[Contractor]="Quechan"))} -> 13000 | I17: {=_xlfn._xlws.FILTER(Table1[CY 2026],(Table1[Contractor]="Quechan"))} -> 13000 | K17: =SUM(F17:I17) -> 52000 | X17: Metropolitan Water District (MWD) of Southern California ICS Creation | Y17: 450000 | Z17: 0 | AA17: 0 | AB17: 0 | AC17: =SUM(Y17:AB17) -> 450000
A18: =MATCH(E18,$E$28:$E$47,0) -> 15 | E18: PVID-MWD System Conservation | F18: {=_xlfn._xlws.FILTER(Table1[CY 2023],(Table1[Contractor]="PVID"))} -> 71507 | G18: {=_xlfn._xlws.FILTER(Table1[CY 2024],(Table1[Contractor]="PVID"))} -> 117021 | H18: {=_xlfn._xlws.FILTER(Table1[CY 2025],(Table1[Contractor]="PVID"))} -> 117021 | I18: {=_xlfn._xlws.FILTER(Table1[CY 2026],(Table1[Contractor]="PVID"))} -> 119338 | K18: =SUM(F18:I18) -> 424887 | X18: MWD Other Conserved Water Left in Lake Mead | Y18: 25066 | Z18: 0 | AA18: 0 | AB18: 0 | AC18: =SUM(Y18:AB18) -> 25066
A19: =MATCH(E19,$E$28:$E$47,0) -> #N/A | E19: Pilot System Conservation Program | F19: 201 | G19: 545 | H19: 545 | I19: 545 | K19: =SUM(F19:I19) -> 1836 | L19: Not for SEIS Volumes | X19: Palo Verde Irrigation District/MWD SCW | Y19: {=_xlfn._xlws.FILTER(Table1[CY 2023],(Table1[Contractor]="PVID"))} -> 71507 | Z19: {=_xlfn._xlws.FILTER(Table1[CY 2024],(Table1[Contractor]="PVID"))} -> 117021 | AA19: {=_xlfn._xlws.FILTER(Table1[CY 2025],(Table1[Contractor]="PVID"))} -> 117021 | AB19: {=_xlfn._xlws.FILTER(Table1[CY 2026],(Table1[Contractor]="PVID"))} -> 119338 | AC19: =SUM(Y19:AB19) -> 424887
A20: =MATCH(E20,$E$28:$E$47,0) -> #N/A | E20: 242 Wellfield Additional Pumping Agreement | F20: {=_xlfn._xlws.FILTER(Table1[CY 2023],(Table1[Contractor]="242 Wellfield"))} -> 7007 | G20: {=_xlfn._xlws.FILTER(Table1[CY 2024],(Table1[Contractor]="242 Wellfield"))} -> 22169 | H20: {=_xlfn._xlws.FILTER(Table1[CY 2025],(Table1[Contractor]="242 Wellfield"))} -> 32000 | I20: {=_xlfn._xlws.FILTER(Table1[CY 2026],(Table1[Contractor]="242 Wellfield"))} -> 50000 | K20: =SUM(F20:I20) -> 111176 | L20: Not for SEIS Volumes | X20: Bard/MWD SCW | Y20: {=_xlfn._xlws.FILTER(Table1[CY 2023],(Table1[Contractor]="Bard"))} -> 0 | Z20: {=_xlfn._xlws.FILTER(Table1[CY 2024],(Table1[Contractor]="Bard"))} -> 5700 | AA20: {=_xlfn._xlws.FILTER(Table1[CY 2025],(Table1[Contractor]="Bard"))} -> 9286 | AB20: {=_xlfn._xlws.FILTER(Table1[CY 2026],(Table1[Contractor]="Bard"))} -> 11400 | AC20: =SUM(Y20:AB20) -> 26386
E21: Annual Total (Non-Shortage/DCP) | F21: =SUM(F4:F20) -> 545308 | G21: =SUM(G4:G20) -> 775521.5 | H21: =SUM(H4:H20) -> 779899.5 | I21: =SUM(I4:I20) -> 675067 | K21: =SUM(K4:K20) -> 2775796 | X21: Quechan Indian Tribe/MWD SCW | Y21: {=_xlfn._xlws.FILTER(Table1[CY 2023],(Table1[Contractor]="Quechan"))} -> 13000 | Z21: {=_xlfn._xlws.FILTER(Table1[CY 2024],(Table1[Contractor]="Quechan"))} -> 13000 | AA21: {=_xlfn._xlws.FILTER(Table1[CY 2025],(Table1[Contractor]="Quechan"))} -> 13000 | AB21: {=_xlfn._xlws.FILTER(Table1[CY 2026],(Table1[Contractor]="Quechan"))} -> 13000 | AC21: =SUM(Y21:AB21) -> 52000
E22: Cumulative Total | F22: =F21 -> 545308 | G22: =F22+G21 -> 1320829.5 | H22: =G22+H21 -> 2100729 | I22: =H22+I21 -> 2775796 | W22: NV | X22: SNWA Other Conserved Water Left in Lake Mead | Y22: 88156 | Z22: 74572 | AA22: 82000 | AB22: 86000 | AC22: =SUM(Y22:AB22) -> 330728
X23: SNWA Tributary ICS Creation | Y23: 36075 | Z23: 34375 | AA23: 35000 | AB23: 35000 | AC23: =SUM(Y23:AB23) -> 140450
X24: Annual Total | Y24: =SUM(Y3:Y23) -> 1179173 | Z24: =SUM(Z3:Z23) -> 867454.5 | AA24: =SUM(AA3:AA23) -> 873640.5 | AB24: =SUM(AB3:AB23) -> 756922 | AC24: =SUM(AC3:AC23) -> 3677190
X25: Cumulative Total | Y25: =Y24 -> 1179173 | Z25: =Y25+Z24 -> 2046627.5 | AA25: =Z25+AA24 -> 2920268 | AB25: =AA25+AB24 -> 3677190
B27: Bucket | C27: State | D27: In Dan's Slide | E27: Conservation Activity (ac-ft) | F27: 2023 | G27: 2024 | H27: 2025 | I27: 2026 | K27: Total
B28: SysCon | C28: AZ | D28: X | E28: CAP System Conservation Agreements | F28: 141400 | G28: 129400 | H28: 128800 | I28: 2400 | K28: =SUM(F28:I28) -> 402000
B29: SysCon | C29: AZ | D29: X | E29: Cathcart Farms System Conservation | F29: 57 | G29: 60.5 | H29: 60.5 | I29: 0 | K29: =SUM(F29:I29) -> 178 | M29: =42+163 -> 205 | Z29: =Z24-Z16 -> 609814.5 | AA29: =AA24-AA16 -> 623640.5 | AB29: =AB24-AB16 -> 564562
B30: SysCon | C30: AZ | D30: X | E30: Cibola Valley IDD System Conservation | F30: 1682 | G30: 2328 | H30: 2328 | I30: 0 | K30: =SUM(F30:I30) -> 6338
B31: SysCon | C31: AZ | D31: X | E31: Fort McDowell Yavapai Nation System Conservation | F31: 13933 | G31: 13933 | H31: 13933 | I31: 0 | K31: =SUM(F31:I31) -> 41799
B32: SysCon | C32: AZ | D32: X | E32: GM Gabrych System Conservation | F32: 3240 | G32: 3240 | H32: 3240 | I32: 0 | K32: =SUM(F32:I32) -> 9720
B33: SysCon | C33: AZ | D33: X | E33: GRIC System Conservation | F33: 91319 | G33: 125000 | H33: 125000 | I33: 51650 | K33: =SUM(F33:I33) -> 392969
B34: SysCon | C34: AZ | D34: X | E34: Hopi Tribe System Conservation | F34: 2679 | G34: 3059 | H34: 3059 | I34: 0 | K34: =SUM(F34:I34) -> 8797
B35: SysCon | C35: AZ | D35: X | E35: MVIDD System Conservation | F35: 12812 | G35: 13441 | H35: 13441 | I35: 0 | K35: =SUM(F35:I35) -> 39694
B36: SysCon | C36: AZ | D36: X | E36: San Carlos Apache Tribe System Conservation | F36: 23804 | G36: 23451 | H36: 23451 | I36: 0 | K36: =SUM(F36:I36) -> 70706
B37: SysCon | C37: AZ | D37: X | E37: YMIDD System Conservation | F37: 21556 | G37: 21795 | H37: 21795 | I37: 0 | K37: =SUM(F37:I37) -> 65146
B38: SEIS | C38: AZ | D38: X | E38: CAP ICS Preservation Program | F38: 41776 | G38: 0 | H38: 0 | I38: 0 | K38: =SUM(F38:I38) -> 41776
B39: SysCon | C39: CA | D39: X | E39: Coachella Groundwater System Conservation | F39: 35000 | G39: 35000 | H39: 35000 | I39: 0 | K39: =SUM(F39:I39) -> 105000
B40: SysCon | C40: CA | D40: X | E40: Coachella Ag Conservation System Conservation | F40: {=_xlfn._xlws.FILTER(Table1[CY 2023],(Table1[Contractor]="CVWD Fallowing"))} -> 0 | G40: {=_xlfn._xlws.FILTER(Table1[CY 2024],(Table1[Contractor]="CVWD Fallowing"))} -> 725 | H40: {=_xlfn._xlws.FILTER(Table1[CY 2025],(Table1[Contractor]="CVWD Fallowing"))} -> 3889 | I40: {=_xlfn._xlws.FILTER(Table1[CY 2026],(Table1[Contractor]="CVWD Fallowing"))} -> 6511 | K40: =SUM(F40:I40) -> 11125
B41: SysCon | C41: CA | D41: X | E41: IID System Conservation | F41: 106111 | G41: 220000 | H41: 240000 | I41: 240000 | K41: =SUM(F41:I41) -> 806111 | M41: State | N41: 2023 | O41: 2024 | P41: 2025 | Q41: 2026 | R41: 2027 | S41: Total
B42: SysCon | C42: CA | D42: X | E42: PVID-MWD System Conservation | F42: 71507 | G42: 117021 | H42: 117021 | I42: 79830 | K42: =SUM(F42:I42) -> 385379 | M42: AZ | N42: =SUM(F52:F62) -> 354530 | O42: =SUM(G52:G62) -> 305970.5 | P42: =SUM(H52:H62) -> 304993.5 | Q42: =SUM(I52:I62) -> 234862 | R42: =SUM(J52:J62) -> 74805 | S42: =SUM(N42:R42) -> 1275161
...

Sheet DCP Bank
A1: MOST PROBABLE - ORIGINAL
A2: 46031
B3: 2026 | C3: 2027 | D3: 2028
A4: AZ | B4: 600000 | C4: 599741
A5: CA | B5: 1650000 | C5: 1650000
A6: NV | B6: 450000 | C6: 450259
A7: Total | B7: =SUM(B4:B6) -> 2700000 | C7: =SUM(C4:C6) -> 2700000 | D7: =SUM(D4:D6) -> 0
B8: =B7-2700000 -> 0 | C8: =C7-2700000 -> 0 | D8: =D7-2700000 -> -2700000
A13: MAX PROBABLE - ORIGINAL
A14: =A2 -> 46031
B15: 2026 | C15: 2027 | D15: 2028
A16: AZ | B16: 600000 | C16: 599741 | D16: 0
A17: CA | B17: 1650000 | C17: 1650000 | D17: 0
A18: NV | B18: 450000 | C18: 450259 | D18: 0
A19: Total | B19: =SUM(B16:B18) -> 2700000 | C19: =SUM(C16:C18) -> 2700000 | D19: =SUM(D16:D18) -> 0
C20: =C19-2700000 -> 0 | D20: =D19-2700000 -> -2700000
D23: =2700000-C23 -> 2700000
A24: MIN PROBABLE - ORIGINAL
A25: =A2 -> 46031
B26: 2026 | C26: 2027 | D26: 2028
A27: AZ | B27: 664179 | C27: 656789
A28: CA | B28: 1419799 | C28: 1169574
A29: NV | B29: 478362 | C29: 549462
A30: Total | B30: =SUM(B27:B29) -> 2562340 | C30: =SUM(C27:C29) -> 2375825 | D30: =SUM(D27:D29) -> 0
C31: =C30-2700000 -> -324175 | D31: =D30-2700000 -> -2700000
A34: ESP MeadBankParameters
B35: Max Capacity | C35: Max Creation | D35: Max Delivery
B36: 1000 acre-ft | C36: 1000 acre-ft | D36: 1000 acre-ft
A37: 0: Arizona | B37: 691 | C37: 185 | D37: 300
A38: 1: California | B38: 1417 | C38: 350 | D38: 400
A39: 2: Nevada | B39: 592 | C39: 90 | D39: 300
A40: 3: Mexico | B40: 1500 | C40: 250 | D40: 200
A41: 4: MWD | B41: 1367 | C41: NaN | D41: NaN
A42: 5: IID | B42: 50 | C42: NaN | D42: NaN
A43: 6: CAWCD | B43: 391 | C43: NaN | D43: NaN
A44: 7: AZTribal | B44: 300 | C44: NaN | D44: NaN

Sheet 500+ Plan Tracking
B1: Baseline - Based on June 2021 24-Month Study Assumptions | J1: Based on July 2023 24-Month Study Assumptions | R1: Difference: APR23 minus JUL21
B2: --Subject to change, based on review as part of 1030 modeling efforts | J2: --Most Probable | R2: --Most Probable | Z2: Table for Water Use Assumptions
B4: Project | C4: State | D4: 24-Month Study | J4: Project | K4: State | L4: 24-Month Study | R4: Project | S4: State | T4: 24-Month Study | Z4: --Most Probable
D5: 2021 | E5: 2022 | F5: 2023 | L5: 2021 | M5: 2022 | N5: 2023 | T5: 2021 | U5: 2022 | V5: 2023
B6: CAWCD ICS | C6: AZ | D6: 0 | E6: -69100 | F6: -69100 | J6: CAWCD ICS | K6: AZ | L6: 6147 | M6: -52841 | N6: =-'OLD 2023'!$B$28 -> -28160 | R6: CAWCD ICS | S6: AZ | T6: =L6-D6 -> 6147 | U6: =M6-E6 -> 16259 | V6: =N6-F6 -> 40940
B7: CRIT System Conservation Water | C7: AZ | D7: 50000 | E7: 50000 | F7: 0 | J7: CRIT System Conservation Water | K7: AZ | L7: 50000 | M7: 50000 | N7: 0 | R7: CRIT System Conservation Water | S7: AZ | T7: =L7-D7 -> 0 | U7: =M7-E7 -> 0 | V7: =N7-F7 -> 0 | Z7: Conservation Activity (volumes in AF) | AA7: 2021 | AB7: 2022 (Provisional) | AC7: 2023 (Projected)
B8: CRIT ICS | C8: AZ | D8: 4685 | E8: 4685 | F8: 0 | J8: CRIT ICS | K8: AZ | L8: 4685 | M8: 4685 | N8: 0 | R8: CRIT ICS | S8: AZ | T8: =L8-D8 -> 0 | U8: =M8-E8 -> 0 | V8: =N8-F8 -> 0 | Z8: CAP ICS delivery offset | AA8: =T6 -> 6147 | AB8: =U6 -> 16259 | AC8: =V6 -> 40940
B9: CRIT ICS to System Conservation | C9: AZ | D9: 0 | E9: 0 | F9: 0 | J9: CRIT ICS to System Conservation | K9: AZ | L9: 4685 | M9: 4685 | N9: 0 | R9: CRIT ICS to System Conservation | S9: AZ | T9: =L9-D9 -> 4685 | U9: =M9-E9 -> 4685 | V9: =N9-F9 -> 0 | Z9: GRIC System Conservation | AA9: =T12 -> 40000 | AB9: =U12 -> 58837 | AC9: =V12 -> 125000
B10: GRIC ICS | C10: AZ | D10: 40000 | E10: 0 | F10: 0 | J10: GRIC ICS | K10: AZ | L10: 40000 | M10: 78565 | N10: 0 | R10: GRIC ICS | S10: AZ | T10: =L10-D10 -> 0 | U10: =M10-E10 -> 78565 | V10: =N10-F10 -> 0 | Z10: GRIC ICS creation | AA10: =T10 -> 0 | AB10: =U10 -> 78565 | AC10: =V10 -> 0
B11: BHC PSCP | C11: AZ | D11: 360 | E11: 400 | F11: 400 | J11: BHC PSCP | K11: AZ | L11: 369 | M11: 132 | N11: 500 | R11: BHC PSCP | S11: AZ | T11: 0 | U11: 0 | V11: =N11-F11 -> 100 | Z11: CRIT System Conservation (in lieu of ICS) | AA11: =T9 -> 4685 | AB11: =U9 -> 4685 | AC11: =V9 -> 0
B12: GRIC System Conservation Water | C12: AZ | D12: 0 | E12: 0 | F12: 0 | J12: GRIC System Conservation Water | K12: AZ | L12: 40000 | M12: 58837 | N12: 125000 | R12: GRIC System Conservation Water | S12: AZ | T12: =L12-D12 -> 40000 | U12: =M12-E12 -> 58837 | V12: =N12-F12 -> 125000 | Z12: CAWCD System Conservation | AA12: =T17 -> 0 | AB12: =U17 -> 87794 | AC12: =V17 -> 141400
B13: MVIDD System Conservation Water | C13: AZ | D13: 6925 | E13: 0 | F13: 0 | J13: MVIDD System Conservation Water | K13: AZ | L13: 6925 | M13: 9531 | N13: 12819 | R13: MVIDD System Conservation Water | S13: AZ | T13: =L13-D13 -> 0 | U13: =M13-E13 -> 9531 | V13: =N13-F13 -> 12819 | Z13: YMIDD System Conservation | AA13: =T15 -> 0 | AB13: =U15 -> 8523 | AC13: =V15 -> 13670
B14: FMYN System Conservation Water | C14: AZ | D14: 13933 | E14: 13933 | F14: 0 | J14: FMYN System Conservation Water | K14: AZ | L14: 13933 | M14: 13933 | N14: 13933 | R14: FMYN System Conservation Water | S14: AZ | T14: =L14-D14 -> 0 | U14: =M14-E14 -> 0 | V14: =N14-F14 -> 13933 | Z14: MVIDD System Conservation | AA14: =T13 -> 0 | AB14: =U13 -> 9531 | AC14: =V13 -> 12819
B15: YMIDD System Conservation Water | C15: AZ | D15: 0 | E15: 0 | F15: 0 | J15: YMIDD System Conservation Water | K15: AZ | L15: 0 | M15: 8523 | N15: 13670 | R15: YMIDD System Conservation Water | S15: AZ | T15: =L15-D15 -> 0 | U15: =M15-E15 -> 8523 | V15: =N15-F15 -> 13670 | Z15: FMYN System Conservation | AA15: =T14 -> 0 | AB15: =U14 -> 0 | AC15: =V14 -> 13933
B16: Gabrych System Conservation Water | C16: AZ | D16: 0 | E16: 0 | F16: 0 | J16: Gabrych System Conservation Water | K16: AZ | L16: 0 | M16: 0 | N16: 3240 | R16: Gabrych System Conservation Water | S16: AZ | T16: =L16-D16 -> 0 | U16: =M16-E16 -> 0 | V16: =N16-F16 -> 3240 | Z16: Gabrych System Conservation | AA16: =T16 -> 0 | AB16: =U16 -> 0 | AC16: =V16 -> 3240
B17: CAWCD System Conservation Water | C17: AZ | D17: 0 | E17: 0 | F17: 0 | J17: CAWCD System Conservation Water | K17: AZ | L17: 0 | M17: 87794 | N17: ='System Conservation'!S2 -> 141400 | R17: CAWCD System Conservation Water | S17: AZ | T17: =L17-D17 -> 0 | U17: =M17-E17 -> 87794 | V17: =N17-F17 -> 141400 | Z17: MWD ICS delivery offset and/or creation | AA17: =T18 -> 58134 | AB17: =U18 -> 32391 | AC17: =V18 -> 470243
B18: MWD ICS | C18: CA | D18: -76920 | E18: -143783 | F18: -20243 | J18: MWD ICS | K18: CA | L18: -18786 | M18: -111392 | N18: =-'OLD 2023'!B8 -> 450000 | R18: MWD ICS | S18: CA | T18: =L18-D18 -> 58134 | U18: =M18-E18 -> 32391 | V18: =N18-F18 -> 470243 | Z18: PVID System Conservation | AA18: =T21 -> 12305 | AB18: =U21 -> 52921 | AC18: =V21 -> 58400
B19: IID ICS | C19: CA | D19: 1579 | E19: 0 | F19: 0 | J19: IID ICS | K19: CA | L19: 1579 | M19: 0 | N19: 0 | R19: IID ICS | S19: CA | T19: =L19-D19 -> 0 | U19: =M19-E19 -> 0 | V19: =N19-F19 -> 0 | Z19: CVWD System Conservation | AA19: =T22 -> 0 | AB19: =U22 -> 9083 | AC19: =V22 -> 0
B20: Needles PSCP | C20: CA | D20: 145 | E20: 145 | F20: 145 | J20: Needles PSCP | K20: CA | L20: 175 | M20: 141 | N20: 145 | R20: Needles PSCP | S20: CA | T20: =L20-D20 -> 30 | U20: =M20-E20 -> -4 | V20: =N20-F20 -> 0 | Z20: IID System Conservation | AA20: =T23 -> 0 | AB20: =U23 -> 25000 | AC20: =V23 -> 0
B21: PVID System Conservation Water | C21: CA | D21: 0 | E21: 0 | F21: 0 | J21: PVID System Conservation Water | K21: CA | L21: 12305 | M21: 52921 | N21: 58400 | R21: PVID System Conservation Water | S21: CA | T21: =L21-D21 -> 12305 | U21: =M21-E21 -> 52921 | V21: =N21-F21 -> 58400 | Z21: SNWA ICS creation | AA21: =T24 -> 12832 | AB21: =U24 -> 28330 | AC21: =V24 -> 44000
B22: CVWD System Conservation | C22: CA | D22: 0 | E22: 0 | F22: 0 | J22: CVWD System Conservation | K22: CA | L22: 0 | M22: 9083 | N22: 0 | R22: CVWD System Conservation | S22: CA | T22: =L22-D22 -> 0 | U22: =M22-E22 -> 9083 | V22: =N22-F22 -> 0 | Z22: Total (Non-Shortage/DCP) | AA22: =SUM(AA8:AA21) -> 134103 | AB22: =SUM(AB8:AB21) -> 411919 | AC22: =SUM(AC8:AC21) -> 923645
B23: IID System Conservation | C23: CA | D23: 0 | E23: 0 | F23: 0 | J23: IID System Conservation | K23: CA | L23: 0 | M23: 25000 | N23: 0 | R23: IID System Conservation | S23: CA | T23: =L23-D23 -> 0 | U23: =M23-E23 -> 25000 | V23: =N23-F23 -> 0 | Z23: Cumulative | AA23: =AA22 -> 134103 | AB23: =AA23+AB22 -> 546022 | AC23: =AB23+AC22 -> 1469667
B24: SNWA ICS | C24: NV | D24: 37000 | E24: 27000 | F24: 18000 | J24: SNWA ICS | K24: NV | L24: 49832 | M24: 55330 | N24: 62000 | R24: SNWA ICS | S24: NV | T24: =L24-D24 -> 12832 | U24: =M24-E24 -> 28330 | V24: =N24-F24 -> 44000
B25: SNWA Tributary Conservation ICS | C25: NV | D25: 30000 | E25: 30000 | F25: 30000 | J25: SNWA Tributary Conservation ICS | K25: NV | L25: 35408 | M25: 35678 | N25: 30000 | R25: SNWA Tributary Conservation ICS | S25: NV | T25: =L25-D25 -> 5408 | U25: =M25-E25 -> 5678 | V25: =N25-F25 -> 0
B26: LB Total (Non-Shrt/DCP) | C26: LB | D26: =SUM(D6:D25) -> 107707 | E26: =SUM(E6:E25) -> -86720 | F26: =SUM(F6:F25) -> -40798 | J26: LB Total (Non-Shrt/DCP) | K26: LB | L26: =SUM(L6:L25) -> 247257 | M26: =SUM(M6:M25) -> 330605 | N26: =SUM(N6:N25) -> 882947 | R26: LB Total (Non-Shrt/DCP) | S26: LB | T26: =SUM(T6:T25) -> 139541 | U26: =SUM(U6:U25) -> 417593 | V26: =SUM(V6:V25) -> 923745 | Z26: 500 + Plan Goal | AB26: 500000 | AC26: 500000
J27: 242 wellfield | L27: 8813 | M27: 14665 | Z27: Increase needed to achieve goal (Most Probable) | AB27: =AB26-AB22 -> 88081 | AC27: =AC26-AC21 -> 456000
B29: LB Shortage | C29: LB | D29: 0 | E29: 333000 | F29: 417000
B30: LB DCP | C30: LB | D30: 211392 | E30: 200000 | F30: 200000 | J30: =J1 -> Based on July 2023 24-Month Study Assumptions | R30: =R1 -> Difference: APR23 minus JUL21
B31: LB Total | C31: LB | D31: =D26+D29+D30 -> 319099 | E31: =E26+E29+E30 -> 446280 | F31: =F26+F29+F30 -> 576202 | J31: -- Probable Minimum | R31: -- Probable Minimum | Z31: -- Probable Minimum
J33: Project | K33: State | L33: 24-Month Study | R33: Project | S33: State | T33: 24-Month Study | Z33: Conservation Activity (volumes in AF) | AA33: 2021 | AB33: 2022 (Provisional) | AC33: 2023 (Projected)
B34: AZ Total (Non-Shrt/DCP) | C34: AZ | D34: =SUM(D6:D14) -> 115903 | E34: =SUM(E6:E14) -> -82 | F34: =SUM(F6:F14) -> -68700 | L34: 2021 | M34: 2022 | N34: 2023 | T34: 2021 | U34: 2022 | V34: 2023 | Z34: CAP ICS delivery offset | AA34: =T35 -> 6147 | AB34: =U35 -> 16259 | AC34: =V35 -> 40940
J35: CAWCD ICS | K35: AZ | L35: 6147 | M35: =M6 -> -52841 | N35: =-'OLD 2023'!G28 -> -28160 | R35: CAWCD ICS | S35: AZ | T35: =L35-D6 -> 6147 | U35: =M35-E6 -> 16259 | V35: =N35-F6 -> 40940 | Z35: GRIC System Conservation | AA35: =T41 -> 40000 | AB35: =U41 -> 58837 | AC35: =V41 -> 125000
J36: CRIT System Conservation Water | K36: AZ | L36: 50000 | M36: =M7 -> 50000 | N36: 0 | R36: CRIT System Conservation Water | S36: AZ | T36: =L36-D7 -> 0 | U36: =M36-E7 -> 0 | V36: =N36-F7 -> 0 | Z36: GRIC ICS creation | AA36: =T39 -> 0 | AB36: =U39 -> 78565 | AC36: =V39 -> 0
J37: CRIT ICS | K37: AZ | L37: 4685 | M37: =M8 -> 4685 | N37: 0 | R37: CRIT ICS | S37: AZ | T37: =L37-D8 -> 0 | U37: =M37-E8 -> 0 | V37: =N37-F8 -> 0 | Z37: CRIT System Conservation (in lieu of ICS) | AA37: =T38 -> 4685 | AB37: =U38 -> 4685 | AC37: =V38 -> 0
J38: CRIT ICS to System Conservation | K38: AZ | L38: 4685 | M38: =M9 -> 4685 | N38: 0 | R38: CRIT ICS to System Conservation | S38: AZ | T38: =L38-D9 -> 4685 | U38: =M38-E9 -> 4685 | V38: =N38-F9 -> 0 | Z38: CAWCD System Conservation | AA38: =T46 -> 0 | AB38: =U46 -> 87794 | AC38: =V46 -> 141400
B39: CA Total (Non-Shrt/DCP) | C39: CA | D39: =SUM(D18:D20) -> -75196 | E39: =SUM(E18:E20) -> -143638 | F39: =SUM(F18:F20) -> -20098 | J39: GRIC ICS | K39: AZ | L39: 40000 | M39: =M10 -> 78565 | N39: 0 | R39: GRIC ICS | S39: AZ | T39: =L39-D10 -> 0 | U39: =M39-E10 -> 78565 | V39: =N39-F10 -> 0 | Z39: YMIDD System Conservation | AA39: =T44 -> 0 | AB39: =U44 -> 8523 | AC39: =V44 -> 13670
J40: BHC PSCP | K40: AZ | L40: 369 | M40: =M11 -> 132 | N40: 500 | R40: BHC PSCP | S40: AZ | T40: =L40-D11 -> 9 | U40: =M40-E11 -> -268 | V40: =N40-F11 -> 100 | Z40: MVIDD System Conservation | AA40: =T42 -> 0 | AB40: =U42 -> 9531 | AC40: =V42 -> 12819
J41: GRIC System Conservation Water | K41: AZ | L41: 40000 | M41: =M12 -> 58837 | N41: 125000 | R41: GRIC System Conservation Water | S41: AZ | T41: =L41-D12 -> 40000 | U41: =M41-E12 -> 58837 | V41: =N41-F12 -> 125000 | Z41: FMYN System Conservation | AA41: =T43 -> 0 | AB41: =U43 -> 0 | AC41: =V43 -> 13933
B42: NV Total (Non-Shrt/DCP) | C42: NV | D42: =SUM(D24:D25) -> 67000 | E42: =SUM(E24:E25) -> 57000 | F42: =SUM(F24:F25) -> 48000 | J42: MVIDD System Conservation Water | K42: AZ | L42: 6925 | M42: =M13 -> 9531 | N42: 12819 | R42: MVIDD System Conservation Water | S42: AZ | T42: =L42-D13 -> 0 | U42: =M42-E13 -> 9531 | V42: =N42-F13 -> 12819 | Z42: Gabrych System Conservation | AA42: =T45 -> 0 | AB42: =U45 -> 0 | AC42: =V45 -> 3240
J43: FMYN System Conservation Water | K43: AZ | L43: 13933 | M43: =M14 -> 13933 | N43: 13933 | R43: FMYN System Conservation Water | S43: AZ | T43: =L43-D14 -> 0 | U43: =M43-E14 -> 0 | V43: =N43-F14 -> 13933 | Z43: MWD ICS delivery offset and/or creation | AA43: =T47 -> 58134 | AB43: =U47 -> 32391 | AC43: =V47 -> 470243
...

Sheet Reductions for MSCP
B2: 45054
B3: Volume Reduction Below Hoover
C4: 2023 | D4: 2024 | E4: 2025
B5: MOST | C5: 906442 | D5: 585119 | E5: 635119
B6: MIN | C6: 754811 | D6: 445119 | E6: 577718
B7: MAX
B9: =B2 -> 45054
B10: Available Volume below 845 KAF
C11: 2023 | D11: 2024 | E11: 2025
B12: MOST | C12: =845000-C5 -> -61442 | D12: =845000-D5 -> 259881 | E12: =845000-E5 -> 209881
B13: MIN | C13: =845000-C6 -> 90189 | D13: =845000-D6 -> 399881 | E13: =845000-E6 -> 267282
B14: MAX | C14: =845000-C7 -> 845000 | D14: =845000-D7 -> 845000 | E14: =845000-E7 -> 845000

Sheet Effective Elevations
A1: MOST | B1: 44958
K2: MOST
B3: Powell Physical Storage | C3: Powell Effective Storage | D3: Mead Physical Storage | E3: Mead Effective Storage | G3: Diff - Effective Storage | H3: Diff - Physical Storage | N3: Physical Elevation | O3: Effective Elevation
A4: 45170 | B4: 7548.72 | C4: 7068.72 | D4: 6588.72 | E4: 7068.72 | G4: =C4-E4 -> 0 | H4: =B4-D4 -> 960 | L4: Powell | M4: 45170 | N4: 3556.61 | O4: 3549.56
A5: 45536 | B5: 8512.94 | C5: 8032.94 | D5: 5520.23 | E5: 6000.23 | G5: =C5-E5 -> 2032.71 | H5: =B5-D5 -> 2992.71 | L5: Mead | M5: 45170 | N5: 1034.27 | O5: 1041.32
A6: 45901 | B6: 9871.8 | C6: 9391.8 | D6: 4559.87 | E6: 5039.87 | G6: =C6-E6 -> 4351.93 | H6: =B6-D6 -> 5311.93 | L6: Powell | M6: 45282 | N6: 3552 | O6: 3544.75
L7: Mead | M7: 45282 | N7: 1034.62 | O7: 1041.65
A8: Tier Determination Elev | B8: 2023 | C8: 2024 | L8: Powell | M8: 45536 | N8: 3569.93 | O8: 3563.44
A9: Powell | B9: 3538.66 | C9: 3555.07 | L9: Mead | M9: 45536 | N9: 1017.68 | O9: 1025.3
A10: Mead | B10: 1041.65 | C10: 1026.11 | L10: Powell | M10: 45648 | N10: 3567.21 | O10: 3560.6
L11: Mead | M11: 45648 | N11: 1018.52 | O11: 1026.11
A13: MIN | B13: 44958 | K13: MIN
